## 协程上下文

**概念：**

CoroutineContext是一组用于定义协程行为的元素。它由如下几项构成：

- Job：控制协程的生命周期
- CoroutineDispatcher：向合适的线程分发任务
- CoroutineName：协程的名称，调试的时候很有用
- CoroutineExceptionHandler:处理未被捕捉的异常

```kotlin
fun coroutineContext() = runBlocking<Unit> {
        launch(Dispatchers.Default +CoroutineName("test")) {
        	println("I'm working in thread ${Thread.currentThread().name}")

    }
```

1. 对于新创建的协程，它的CoroutineContex会包含一个全新的Job实例，它会帮助我们控制协程的生命周期。而剩下的元素会从CoroutineContext的父类继承，该父类可能是另外一个协程或者创建该协程的CoroutineScope。

   ```kotlin
   // 上下文的继承
   fun coroutineContext_extend () = runBlocking<Unit> { // this: CoroutineScope
       
   	val scope = CoroutineScope (Job () + Dispatchers.I0 + CoroutineName ("test"))
       
   	val job = scope.launch { // this: CoroutineScope
           
   		println("${coroutineContext[Job]} ${Thread.currentThread().name}")
           
   		val result = async { // this: CoroutineScope
   			println("${coroutineContext[Job]} ${Thread.currentThread().name}")
               "DATA"
           }.await()
           println(result)
       }
       job.join()
   }
   
   ```

   

2. 协程的上下文=*默认值 + 继承的CoroutineContext + 参数*

   

   * 一些元素包含默认值：Dispatchers.Default是默认的CoroutineDispatcher,以及"coroutine”作为默认的CoroutineName

   * 继承的CoroutineContext是CoroutineScope或者其父协程的CoroutineContext

   * 传入协程构建器的参数的优先级高于继承的上下文参数，因此会覆盖对应的参数值。

     

### 协程的异常处理

1. 异常的传播

   > 协程构建器有两种形式：
   >
   > **自动传播异常**（launch与actor），**向用户暴露异常**（async与produce）
   >
   > 当这些构建器用于创建一个**根协程**时（该协程不是另一个协程的子协程）:
   >
   > <u>前者这类构建器，异常会在它发生的第一时间被抛出</u>，
   >
   > <u>而后者则依赖用户来最终消费异常，例如通过await或receive</u>。



```kotlin
// 根协程 launch和async协程捕获异常的地方不同
fun exception_propagation () = runBlocking<Unit> {
	val job = GlobalScope.launch { 
		try {
			throw IndexOutOfBoundsException ()
		}catch (e:Exception){
			println ("Caught IndexOutOfBoundsException'")
        }
    }
	job.join()

    val deferred = GlobalScope.async { 
		throw ArithmeticException()
    }
	try {
		deferred.await()
	}catch (e:Exception){
		println ("Caught ArithmeticException'")
    }
}

```

非根协程的异常总是会被向下传播

```kotlin
fun exception_propagation2() = runBlocking<Unit> { // this: CoroutineScope
	val scope = CoroutineScope(Job())
	val job = scope.launch { // this: CoroutineScope
		async { // this: CoroutineScope
            // 非根协程async不用await也会抛出
			throw IllegalArgumentException ()
        }
    }
	job.join()
}

```

2. 异常的传播特点

   当一个协程由于一个异常而运行失败时，它会传播这个异常并传递给它的父级。接下来，父级会进行下面几步操作：

- ​          取消它自己的子级       
- ​         取消它自己    
- ​         将异常传播并传递给它的父级

3. SupervisorJob
   * 使用SupervisorJob时，一个子协程的运行失败不会影响到其他子协程。SupervisorJob不会传播异常给它的父级，它会让子协程自己处理异常。
   * 这种需求常见于在作用域内定义作业的UI组件，如果任何一个UI的子作业执行失败了，它并不总是有必要取消整个UI组件，但是如果UI组件被销毁了，由于它的结果不再被需要了，它就有必要使所有的子作业执行失败。

```kotlin
// SupervisorJob，一个子协程的运行失败不会影响到其他子协程。SupervisorJob不会传播异常给它的父级，它会让子协程自己处理异常
fun supervisorJob() = runBlocking<Unit> { //this: CoroutineScope
	val supervisor = CoroutineScope(SupervisorJob())
	val job1 = supervisor.launch { // this: CoroutineScope
		delay (100)
		println("child 1")
		throw IllegalArgumentException ()
    }
	val job2 = supervisor.launch { // this: CoroutineScope
		try {
			delay (Long.MAX_VALUE)
		}finally {
			println("child 2 finished.")
    	}

		joinAl1(job1,job2)
   }
```



```kotlin
fun supervisorScope() = runBlocking<Unit> { //this: CoroutineScope
	supervisorScope { //this: CoroutineScope
		launch {// this: CoroutineScope
			delay (100)
			println("child 1")
			throw IllegalArgumentException ()
        }
		try {
			delay (Long.MAX_VALUE)
		}finally {
			println("child 2 finished.")
        }
    }
    

```

4. 异常的捕获
   

   * 使用CoroutineExceptionHandler对协程的异常进行捕获。

   * 以下的条件被满足时，异常就会被捕获：
     ●时机：异常是被自动抛出异常的协程所抛出的（使用launch，而不是async时）；

     ●位置：在CoroutineScope的CoroutineContext中或在一个根协程（CoroutineScope或者supervisorScope的直接子协程）中。

```kotlin
fun coroutineExceptionHandler() = runBlocking<Unit> { // this: CoroutineScope
    // 异常捕获器
	val handler = CoroutineExceptionHandler { _, exception ->
		println("Caught $exception")
    }
	val scope = CoroutineScope(Job())
	val job = scope.launch (handler){ //this: CoroutineScope
		launch{ //this: CoroutineScope
			throw IllegalArgumentException ()
   		 }
	}
	job.join()
}
// 可以被捕获，发生异常launch的父节点捕获
```



```kotlin
fun coroutineExceptionHandler() = runBlocking<Unit> { // this: CoroutineScope
    // 异常捕获器
	val handler = CoroutineExceptionHandler { _, exception ->
		println("Caught $exception")
    }
	val scope = CoroutineScope(Job())
	val job = scope.launch{ //this: CoroutineScope
		launch (handler){ //this: CoroutineScope
			throw IllegalArgumentException ()
   		 }
	}
	job.join()
}
// 不可以被捕获，被发生异常launch的父节点截获
```

5. Android中全局异常处理
   * 全局异常处理器可以获取到所有协程未处理的未捕获异常，不过它并不能对异常进行捕获虽然不能阻止程序崩溃，全局异常处理器在程序调试和异常上报等场景中仍然有非常大的用处。
   * 需要在classpath下面创建META-INF/services目录,并在其中创建一个名为kotlinx.coroutines.CoroutineExceptionHandler的文件,文件内容就是我们的全局异常处理器的全类名。全局异常的监控：

```kotlin
// 在main下创建resources->META_INF.services包，创建文件kotlinx.coroutines.CoroutineExceptionHandler

class GlobalCoroutineExceptionHandler :CoroutineExceptionHandler {
	override val key = CoroutineExceptionHandler

    override fun handleException(context: CoroutineContext, exception: Throwable) {
		Log.d (TAG,  "Unhandled Coroutine Exception: $exception")
    }
}

```

6. 异常聚合

   当协程的多个子协程因为异常而失败时，一般情况下取第一个异常进行处理。在第一个异常之后发生的所有其他异常，都将被绑定到第一个异常之上。